<?xml version="1.0" ?>
<robot name="turtlebot3_burger" xmlns:xacro="http://ros.org/wiki/xacro">
  <xacro:include filename="$(find nuturtle_description)/urdf/common_properties.xacro"/>
  
  <xacro:property name="yaml_file" value="$(find nuturtle_description)/config/diff_params.yaml"/>
  <xacro:property name="params" value="${xacro.load_yaml(yaml_file)}"/>
  <xacro:property name="collision_radius" value="${params['collision_radius']}"/>

  <xacro:arg name="color" default="black" />
  <xacro:property name="ns" value="$(arg color)/" />
  <link name="${ns}base_footprint"/>

  <joint name="${ns}base_joint" type="fixed">
    <parent link="${ns}base_footprint"/>
    <child link="${ns}base_link"/>
    <origin xyz="0.0 0.0 0.01" rpy="0 0 0"/>
    <material name="black"/>
  </joint>

  <link name="${ns}base_link">
    <visual>
      <origin xyz="-0.032 0 0.0" rpy="0 0 0"/>
      <geometry>
        <mesh filename="package://nuturtle_description/urdf/meshes/burger_base.stl" scale="0.001 0.001 0.001"/>
      </geometry>
    <material name="$(arg color)"/>
    </visual>

    <collision>
      <origin xyz="-0.032 0 0.070" rpy="0 0 0"/>
      <geometry>
        <xacro:if value="${collision_radius=='0'}">
        <box size="0.140 0.140 0.143"/>
        </xacro:if>
        <xacro:unless value="${collision_radius=='0'}">
         <cylinder length="0.14" radius="${collision_radius}" />
        </xacro:unless>
      </geometry>
    </collision>

    <inertial>
      <origin xyz="0 0 0" rpy="0 0 0"/>
      <mass value="8.2573504e-01"/>
      <inertia ixx="2.2124416e-03" ixy="-1.2294101e-05" ixz="3.4938785e-05"
               iyy="2.1193702e-03" iyz="-5.0120904e-06"
               izz="2.0064271e-03" />
    </inertial>
  </link>

  <joint name="${ns}wheel_left_joint" type="continuous">
    <parent link="${ns}base_link"/>
    <child link="${ns}wheel_left_link"/>
    <origin xyz="0.0 0.08 0.023" rpy="-1.57 0 0"/>
    <axis xyz="0 0 1"/>
    <material name="black"/>
  </joint>

  <link name="${ns}wheel_left_link">
    <visual>
      <origin xyz="0 0 0" rpy="1.57 0 0"/>
      <geometry>
        <mesh filename="package://nuturtle_description/urdf/meshes/left_tire.stl" scale="0.001 0.001 0.001"/>
      </geometry>
    <material name="black"/>
    </visual>

    <collision>
      <origin xyz="0 0 0" rpy="0 0 0"/>
      <geometry>
        <cylinder length="0.018" radius="0.033"/>
      </geometry>
    </collision>

    <inertial>
      <origin xyz="0 0 0" />
      <mass value="2.8498940e-02" />
      <inertia ixx="1.1175580e-05" ixy="-4.2369783e-11" ixz="-5.9381719e-09"
               iyy="1.1192413e-05" iyz="-1.4400107e-11"
               izz="2.0712558e-05" />
      </inertial>
  </link>

  <joint name="${ns}wheel_right_joint" type="continuous">
    <parent link="${ns}base_link"/>
    <child link="${ns}wheel_right_link"/>
    <origin xyz="0.0 -0.080 0.023" rpy="-1.57 0 0"/>
    <axis xyz="0 0 1"/>
    <material name="black"/>
  </joint>

  <link name="${ns}wheel_right_link">
    <visual>
      <origin xyz="0 0 0" rpy="1.57 0 0"/>
      <geometry>
        <mesh filename="package://nuturtle_description/urdf/meshes/right_tire.stl" scale="0.001 0.001 0.001"/>
      </geometry>
    <material name="black"/>
    </visual>

    <collision>
      <origin xyz="0 0 0" rpy="0 0 0"/>
      <geometry>
        <cylinder length="0.018" radius="0.033"/>
      </geometry>
    </collision>

    <inertial>
      <origin xyz="0 0 0" />
      <mass value="2.8498940e-02" />
      <inertia ixx="1.1175580e-05" ixy="-4.2369783e-11" ixz="-5.9381719e-09"
               iyy="1.1192413e-05" iyz="-1.4400107e-11"
               izz="2.0712558e-05" />
      </inertial>
  </link>

  <joint name="${ns}caster_back_joint" type="fixed">
    <parent link="${ns}base_link"/>
    <child link="${ns}caster_back_link"/>
    <origin xyz="-0.081 0 -0.004" rpy="-1.57 0 0"/>
    <material name="black"/>
  </joint>

  <link name="${ns}caster_back_link">
    <collision>
      <origin xyz="0 0.001 0" rpy="0 0 0"/>
      <geometry>
        <box size="0.030 0.009 0.020"/>
      </geometry>
      <material name="$(arg color)"/>
    </collision>

    <inertial>
      <origin xyz="0 0 0" />
      <mass value="0.005" />
      <inertia ixx="0.001" ixy="0.0" ixz="0.0"
               iyy="0.001" iyz="0.0"
               izz="0.001" />
    </inertial>
  </link>

  <joint name="${ns}imu_joint" type="fixed">
    <parent link="${ns}base_link"/>
    <child link="${ns}imu_link"/>
    <origin xyz="-0.032 0 0.068" rpy="0 0 0"/>
    <material name="black"/>
  </joint>

  <link name="${ns}imu_link"/>

  <joint name="${ns}scan_joint" type="fixed">
    <parent link="${ns}base_link"/>
    <child link="${ns}base_scan"/>
    <origin xyz="-0.032 0 0.172" rpy="0 0 0"/>
    <material name="black"/>
  </joint>

  <link name="${ns}base_scan">
    <visual>
      <origin xyz="0 0 0.0" rpy="0 0 0"/>
      <geometry>
        <mesh filename="package://nuturtle_description/urdf/meshes/lds.stl" scale="0.001 0.001 0.001"/>
      </geometry>
    <material name="black"/>
    </visual>

    <collision>
      <origin xyz="0.015 0 -0.0065" rpy="0 0 0"/>
      <geometry>
        <cylinder length="0.0315" radius="0.055"/>
      </geometry>
    </collision>

    <inertial>
      <mass value="0.114" />
      <origin xyz="0 0 0" />
      <inertia ixx="0.001" ixy="0.0" ixz="0.0"
               iyy="0.001" iyz="0.0"
               izz="0.001" />
    </inertial>
  </link>

</robot>
